2025-09-27 10:02:33,234 13768 INFO ? odoo.modules.loading: loading 1 modules... 
2025-09-27 10:02:33,242 13768 INFO ? odoo.modules.loading: 1 modules loaded in 0.00s, 0 queries (+0 extra) 
2025-09-27 10:02:33,255 13768 INFO ? odoo.modules.loading: loading 77 modules... 
2025-09-27 10:02:33,279 13768 INFO ? odoo.modules.loading: Loading module customer_map_tracking (28/77) 
2025-09-27 10:02:33,380 13768 INFO ? odoo.modules.registry: module customer_map_tracking: creating or updating database tables 
2025-09-27 10:02:33,408 13768 WARNING ? odoo.addons.base.models.ir_model: Two fields (location_display, shape) of customer.map() have the same label: Location. [Modules: customer_map_tracking and customer_map_tracking] 
2025-09-27 10:02:33,433 13768 INFO ? odoo.modules.loading: loading customer_map_tracking/security/security.xml 
2025-09-27 10:02:33,504 13768 INFO ? odoo.modules.loading: loading customer_map_tracking/security/ir.model.access.csv 
2025-09-27 10:02:33,521 13768 INFO ? odoo.modules.loading: loading customer_map_tracking/views/customer_map_views.xml 
2025-09-27 10:02:33,540 13768 WARNING ? odoo.addons.base.models.ir_ui_view: set_location_from_coordinates on customer.map has parameters and cannot be called from a button
View error context:
{'file': 'd:\\work-project\\ssi\\odoo_demo\\odoo\\custom_addons\\customer_map_tracking\\views\\customer_map_views.xml',
 'line': 59,
 'name': 'customer.map.form',
 'view': ir.ui.view(1314,),
 'view.model': 'customer.map',
 'view.parent': ir.ui.view(),
 'xmlid': 'view_customer_map_form'} 
2025-09-27 10:02:33,550 13768 INFO ? odoo.modules.loading: loading customer_map_tracking/views/customer_map_geoengine_views.xml 
2025-09-27 10:02:33,574 13768 INFO ? odoo.modules.loading: loading customer_map_tracking/views/customer_map_actions.xml 
2025-09-27 10:02:33,580 13768 WARNING ? odoo.modules.loading: Transient module states were reset 
2025-09-27 10:02:33,580 13768 ERROR ? odoo.modules.registry: Failed to load registry 
Traceback (most recent call last):
  File "D:\work-project\ssi\odoo_demo\odoo\odoo\modules\registry.py", line 87, in __new__
    return cls.registries[db_name]
           ~~~~~~~~~~~~~~^^^^^^^^^
  File "D:\work-project\ssi\odoo_demo\odoo\venv\Lib\site-packages\decorator.py", line 232, in fun
    return caller(func, *(extras + args), **kw)
           ^^^^^^^^^^^^^^^^^^^^^^^^^^^^^^^^^^^^
  File "D:\work-project\ssi\odoo_demo\odoo\odoo\tools\func.py", line 87, in locked
    return func(inst, *args, **kwargs)
           ^^^^^^^^^^^^^^^^^^^^^^^^^^^
  File "D:\work-project\ssi\odoo_demo\odoo\odoo\tools\lru.py", line 34, in __getitem__
    a = self.d[obj]
        ~~~~~~^^^^^
KeyError: 'ssi_odoo_demo'

During handling of the above exception, another exception occurred:

Traceback (most recent call last):
  File "D:\work-project\ssi\odoo_demo\odoo\odoo\tools\cache.py", line 99, in lookup
    r = d[key]
        ~^^^^^
  File "D:\work-project\ssi\odoo_demo\odoo\venv\Lib\site-packages\decorator.py", line 232, in fun
    return caller(func, *(extras + args), **kw)
           ^^^^^^^^^^^^^^^^^^^^^^^^^^^^^^^^^^^^
  File "D:\work-project\ssi\odoo_demo\odoo\odoo\tools\func.py", line 87, in locked
    return func(inst, *args, **kwargs)
           ^^^^^^^^^^^^^^^^^^^^^^^^^^^
  File "D:\work-project\ssi\odoo_demo\odoo\odoo\tools\lru.py", line 34, in __getitem__
    a = self.d[obj]
        ~~~~~~^^^^^
KeyError: ('ir.model.data', <function IrModelData._xmlid_lookup at 0x00000151A4B33920>, 'customer_map_tracking.view_customer_map_geoengine_simple')

During handling of the above exception, another exception occurred:

Traceback (most recent call last):
  File "D:\work-project\ssi\odoo_demo\odoo\odoo\tools\convert.py", line 564, in _tag_root
    f(rec)
  File "D:\work-project\ssi\odoo_demo\odoo\odoo\tools\convert.py", line 429, in _tag_record
    f_val = self.id_get(f_ref, raise_if_not_found=nodeattr2bool(rec, 'forcecreate', True))
            ^^^^^^^^^^^^^^^^^^^^^^^^^^^^^^^^^^^^^^^^^^^^^^^^^^^^^^^^^^^^^^^^^^^^^^^^^^^^^^
  File "D:\work-project\ssi\odoo_demo\odoo\odoo\tools\convert.py", line 546, in id_get
    res = self.model_id_get(id_str, raise_if_not_found)
          ^^^^^^^^^^^^^^^^^^^^^^^^^^^^^^^^^^^^^^^^^^^^^
  File "D:\work-project\ssi\odoo_demo\odoo\odoo\tools\convert.py", line 552, in model_id_get
    return self.env['ir.model.data']._xmlid_to_res_model_res_id(id_str, raise_if_not_found=raise_if_not_found)
           ^^^^^^^^^^^^^^^^^^^^^^^^^^^^^^^^^^^^^^^^^^^^^^^^^^^^^^^^^^^^^^^^^^^^^^^^^^^^^^^^^^^^^^^^^^^^^^^^^^^
  File "D:\work-project\ssi\odoo_demo\odoo\odoo\addons\base\models\ir_model.py", line 2205, in _xmlid_to_res_model_res_id
    return self._xmlid_lookup(xmlid)
           ^^^^^^^^^^^^^^^^^^^^^^^^^
  File "D:\work-project\ssi\odoo_demo\odoo\venv\Lib\site-packages\decorator.py", line 232, in fun
    return caller(func, *(extras + args), **kw)
           ^^^^^^^^^^^^^^^^^^^^^^^^^^^^^^^^^^^^
  File "D:\work-project\ssi\odoo_demo\odoo\odoo\tools\cache.py", line 104, in lookup
    value = d[key] = self.method(*args, **kwargs)
                     ^^^^^^^^^^^^^^^^^^^^^^^^^^^^
  File "D:\work-project\ssi\odoo_demo\odoo\odoo\addons\base\models\ir_model.py", line 2198, in _xmlid_lookup
    raise ValueError('External ID not found in the system: %s' % xmlid)
ValueError: External ID not found in the system: customer_map_tracking.view_customer_map_geoengine_simple

The above exception was the direct cause of the following exception:

Traceback (most recent call last):
  File "D:\work-project\ssi\odoo_demo\odoo\odoo\modules\registry.py", line 110, in new
    odoo.modules.load_modules(registry, force_demo, status, update_module)
  File "D:\work-project\ssi\odoo_demo\odoo\odoo\modules\loading.py", line 481, in load_modules
    processed_modules += load_marked_modules(env, graph,
                         ^^^^^^^^^^^^^^^^^^^^^^^^^^^^^^^
  File "D:\work-project\ssi\odoo_demo\odoo\odoo\modules\loading.py", line 366, in load_marked_modules
    loaded, processed = load_module_graph(
                        ^^^^^^^^^^^^^^^^^^
  File "D:\work-project\ssi\odoo_demo\odoo\odoo\modules\loading.py", line 229, in load_module_graph
    load_data(env, idref, mode, kind='data', package=package)
  File "D:\work-project\ssi\odoo_demo\odoo\odoo\modules\loading.py", line 73, in load_data
    tools.convert_file(env, package.name, filename, idref, mode, noupdate, kind)
  File "D:\work-project\ssi\odoo_demo\odoo\odoo\tools\convert.py", line 635, in convert_file
    convert_xml_import(env, module, fp, idref, mode, noupdate)
  File "D:\work-project\ssi\odoo_demo\odoo\odoo\tools\convert.py", line 701, in convert_xml_import
    obj.parse(doc.getroot())
  File "D:\work-project\ssi\odoo_demo\odoo\odoo\tools\convert.py", line 621, in parse
    self._tag_root(de)
  File "D:\work-project\ssi\odoo_demo\odoo\odoo\tools\convert.py", line 564, in _tag_root
    f(rec)
  File "D:\work-project\ssi\odoo_demo\odoo\odoo\tools\convert.py", line 577, in _tag_root
    raise ParseError('while parsing %s:%s, somewhere inside\n%s' % (
odoo.tools.convert.ParseError: while parsing file:/d:/work-project/ssi/odoo_demo/odoo/custom_addons/customer_map_tracking/views/customer_map_actions.xml:5, somewhere inside
<record id="action_customer_map_dashboard" model="ir.actions.act_window">
            <field name="name">Map Dashboard</field>
            <field name="res_model">customer.map</field>
            <field name="view_mode">geoengine,tree,form</field>
            <field name="view_id" ref="view_customer_map_geoengine_simple"/>
            <field name="domain">[('active', '=', True), ('shape', '!=', False)]</field>
            <field name="context">{
                'create': True,
                'edit': True,
                'delete': False
            }</field>
        </record>
2025-09-27 10:02:33,580 13768 ERROR ? odoo.http: Exception during request handling. 
Traceback (most recent call last):
  File "D:\work-project\ssi\odoo_demo\odoo\odoo\modules\registry.py", line 87, in __new__
    return cls.registries[db_name]
           ~~~~~~~~~~~~~~^^^^^^^^^
  File "D:\work-project\ssi\odoo_demo\odoo\venv\Lib\site-packages\decorator.py", line 232, in fun
    return caller(func, *(extras + args), **kw)
           ^^^^^^^^^^^^^^^^^^^^^^^^^^^^^^^^^^^^
  File "D:\work-project\ssi\odoo_demo\odoo\odoo\tools\func.py", line 87, in locked
    return func(inst, *args, **kwargs)
           ^^^^^^^^^^^^^^^^^^^^^^^^^^^
  File "D:\work-project\ssi\odoo_demo\odoo\odoo\tools\lru.py", line 34, in __getitem__
    a = self.d[obj]
        ~~~~~~^^^^^
KeyError: 'ssi_odoo_demo'

During handling of the above exception, another exception occurred:

Traceback (most recent call last):
  File "D:\work-project\ssi\odoo_demo\odoo\odoo\tools\cache.py", line 99, in lookup
    r = d[key]
        ~^^^^^
  File "D:\work-project\ssi\odoo_demo\odoo\venv\Lib\site-packages\decorator.py", line 232, in fun
    return caller(func, *(extras + args), **kw)
           ^^^^^^^^^^^^^^^^^^^^^^^^^^^^^^^^^^^^
  File "D:\work-project\ssi\odoo_demo\odoo\odoo\tools\func.py", line 87, in locked
    return func(inst, *args, **kwargs)
           ^^^^^^^^^^^^^^^^^^^^^^^^^^^
  File "D:\work-project\ssi\odoo_demo\odoo\odoo\tools\lru.py", line 34, in __getitem__
    a = self.d[obj]
        ~~~~~~^^^^^
KeyError: ('ir.model.data', <function IrModelData._xmlid_lookup at 0x00000151A4B33920>, 'customer_map_tracking.view_customer_map_geoengine_simple')

During handling of the above exception, another exception occurred:

Traceback (most recent call last):
  File "D:\work-project\ssi\odoo_demo\odoo\odoo\tools\convert.py", line 564, in _tag_root
    f(rec)
  File "D:\work-project\ssi\odoo_demo\odoo\odoo\tools\convert.py", line 429, in _tag_record
    f_val = self.id_get(f_ref, raise_if_not_found=nodeattr2bool(rec, 'forcecreate', True))
            ^^^^^^^^^^^^^^^^^^^^^^^^^^^^^^^^^^^^^^^^^^^^^^^^^^^^^^^^^^^^^^^^^^^^^^^^^^^^^^
  File "D:\work-project\ssi\odoo_demo\odoo\odoo\tools\convert.py", line 546, in id_get
    res = self.model_id_get(id_str, raise_if_not_found)
          ^^^^^^^^^^^^^^^^^^^^^^^^^^^^^^^^^^^^^^^^^^^^^
  File "D:\work-project\ssi\odoo_demo\odoo\odoo\tools\convert.py", line 552, in model_id_get
    return self.env['ir.model.data']._xmlid_to_res_model_res_id(id_str, raise_if_not_found=raise_if_not_found)
           ^^^^^^^^^^^^^^^^^^^^^^^^^^^^^^^^^^^^^^^^^^^^^^^^^^^^^^^^^^^^^^^^^^^^^^^^^^^^^^^^^^^^^^^^^^^^^^^^^^^
  File "D:\work-project\ssi\odoo_demo\odoo\odoo\addons\base\models\ir_model.py", line 2205, in _xmlid_to_res_model_res_id
    return self._xmlid_lookup(xmlid)
           ^^^^^^^^^^^^^^^^^^^^^^^^^
  File "D:\work-project\ssi\odoo_demo\odoo\venv\Lib\site-packages\decorator.py", line 232, in fun
    return caller(func, *(extras + args), **kw)
           ^^^^^^^^^^^^^^^^^^^^^^^^^^^^^^^^^^^^
  File "D:\work-project\ssi\odoo_demo\odoo\odoo\tools\cache.py", line 104, in lookup
    value = d[key] = self.method(*args, **kwargs)
                     ^^^^^^^^^^^^^^^^^^^^^^^^^^^^
  File "D:\work-project\ssi\odoo_demo\odoo\odoo\addons\base\models\ir_model.py", line 2198, in _xmlid_lookup
    raise ValueError('External ID not found in the system: %s' % xmlid)
ValueError: External ID not found in the system: customer_map_tracking.view_customer_map_geoengine_simple

The above exception was the direct cause of the following exception:

Traceback (most recent call last):
  File "D:\work-project\ssi\odoo_demo\odoo\odoo\http.py", line 2396, in __call__
    response = request._serve_db()
               ^^^^^^^^^^^^^^^^^^^
  File "D:\work-project\ssi\odoo_demo\odoo\odoo\http.py", line 1949, in _serve_db
    self.registry = Registry(self.db).check_signaling()
                    ^^^^^^^^^^^^^^^^^
  File "D:\work-project\ssi\odoo_demo\odoo\odoo\modules\registry.py", line 89, in __new__
    return cls.new(db_name)
           ^^^^^^^^^^^^^^^^
  File "D:\work-project\ssi\odoo_demo\odoo\venv\Lib\site-packages\decorator.py", line 232, in fun
    return caller(func, *(extras + args), **kw)
           ^^^^^^^^^^^^^^^^^^^^^^^^^^^^^^^^^^^^
  File "D:\work-project\ssi\odoo_demo\odoo\odoo\tools\func.py", line 87, in locked
    return func(inst, *args, **kwargs)
           ^^^^^^^^^^^^^^^^^^^^^^^^^^^
  File "D:\work-project\ssi\odoo_demo\odoo\odoo\modules\registry.py", line 110, in new
    odoo.modules.load_modules(registry, force_demo, status, update_module)
  File "D:\work-project\ssi\odoo_demo\odoo\odoo\modules\loading.py", line 481, in load_modules
    processed_modules += load_marked_modules(env, graph,
                         ^^^^^^^^^^^^^^^^^^^^^^^^^^^^^^^
  File "D:\work-project\ssi\odoo_demo\odoo\odoo\modules\loading.py", line 366, in load_marked_modules
    loaded, processed = load_module_graph(
                        ^^^^^^^^^^^^^^^^^^
  File "D:\work-project\ssi\odoo_demo\odoo\odoo\modules\loading.py", line 229, in load_module_graph
    load_data(env, idref, mode, kind='data', package=package)
  File "D:\work-project\ssi\odoo_demo\odoo\odoo\modules\loading.py", line 73, in load_data
    tools.convert_file(env, package.name, filename, idref, mode, noupdate, kind)
  File "D:\work-project\ssi\odoo_demo\odoo\odoo\tools\convert.py", line 635, in convert_file
    convert_xml_import(env, module, fp, idref, mode, noupdate)
  File "D:\work-project\ssi\odoo_demo\odoo\odoo\tools\convert.py", line 701, in convert_xml_import
    obj.parse(doc.getroot())
  File "D:\work-project\ssi\odoo_demo\odoo\odoo\tools\convert.py", line 621, in parse
    self._tag_root(de)
  File "D:\work-project\ssi\odoo_demo\odoo\odoo\tools\convert.py", line 564, in _tag_root
    f(rec)
  File "D:\work-project\ssi\odoo_demo\odoo\odoo\tools\convert.py", line 577, in _tag_root
    raise ParseError('while parsing %s:%s, somewhere inside\n%s' % (
odoo.tools.convert.ParseError: while parsing file:/d:/work-project/ssi/odoo_demo/odoo/custom_addons/customer_map_tracking/views/customer_map_actions.xml:5, somewhere inside
<record id="action_customer_map_dashboard" model="ir.actions.act_window">
            <field name="name">Map Dashboard</field>
            <field name="res_model">customer.map</field>
            <field name="view_mode">geoengine,tree,form</field>
            <field name="view_id" ref="view_customer_map_geoengine_simple"/>
            <field name="domain">[('active', '=', True), ('shape', '!=', False)]</field>
            <field name="context">{
                'create': True,
                'edit': True,
                'delete': False
            }</field>
        </record>
2025-09-27 10:02:33,595 13768 INFO ? werkzeug: 127.0.0.1 - - [27/Sep/2025 10:02:33] "GET /favicon.ico HTTP/1.1" 500 - 193 0.082 0.283
2025-09-27 10:02:34,217 13768 INFO ? odoo.modules.loading: loading 1 modules... 
2025-09-27 10:02:34,223 13768 INFO ? odoo.modules.loading: 1 modules loaded in 0.01s, 0 queries (+0 extra) 
2025-09-27 10:02:34,273 13768 INFO ? odoo.modules.loading: loading 77 modules... 
2025-09-27 10:02:34,295 13768 INFO ? odoo.modules.loading: Loading module customer_map_tracking (28/77) 
2025-09-27 10:02:34,380 13768 INFO ? odoo.modules.registry: module customer_map_tracking: creating or updating database tables 
2025-09-27 10:02:34,389 13768 WARNING ? odoo.addons.base.models.ir_model: Two fields (location_display, shape) of customer.map() have the same label: Location. [Modules: customer_map_tracking and customer_map_tracking] 
2025-09-27 10:02:34,405 13768 INFO ? odoo.modules.loading: loading customer_map_tracking/security/security.xml 
2025-09-27 10:02:34,473 13768 INFO ? odoo.modules.loading: loading customer_map_tracking/security/ir.model.access.csv 
2025-09-27 10:02:34,481 13768 INFO ? odoo.modules.loading: loading customer_map_tracking/views/customer_map_views.xml 
2025-09-27 10:02:34,498 13768 WARNING ? odoo.addons.base.models.ir_ui_view: set_location_from_coordinates on customer.map has parameters and cannot be called from a button
View error context:
{'file': 'd:\\work-project\\ssi\\odoo_demo\\odoo\\custom_addons\\customer_map_tracking\\views\\customer_map_views.xml',
 'line': 59,
 'name': 'customer.map.form',
 'view': ir.ui.view(1314,),
 'view.model': 'customer.map',
 'view.parent': ir.ui.view(),
 'xmlid': 'view_customer_map_form'} 
2025-09-27 10:02:34,516 13768 INFO ? odoo.modules.loading: loading customer_map_tracking/views/customer_map_geoengine_views.xml 
2025-09-27 10:02:34,530 13768 INFO ? odoo.modules.loading: loading customer_map_tracking/views/customer_map_actions.xml 
2025-09-27 10:02:34,539 13768 WARNING ? odoo.modules.loading: Transient module states were reset 
2025-09-27 10:02:34,539 13768 ERROR ? odoo.modules.registry: Failed to load registry 
Traceback (most recent call last):
  File "D:\work-project\ssi\odoo_demo\odoo\odoo\modules\registry.py", line 87, in __new__
    return cls.registries[db_name]
           ~~~~~~~~~~~~~~^^^^^^^^^
  File "D:\work-project\ssi\odoo_demo\odoo\venv\Lib\site-packages\decorator.py", line 232, in fun
    return caller(func, *(extras + args), **kw)
           ^^^^^^^^^^^^^^^^^^^^^^^^^^^^^^^^^^^^
  File "D:\work-project\ssi\odoo_demo\odoo\odoo\tools\func.py", line 87, in locked
    return func(inst, *args, **kwargs)
           ^^^^^^^^^^^^^^^^^^^^^^^^^^^
  File "D:\work-project\ssi\odoo_demo\odoo\odoo\tools\lru.py", line 34, in __getitem__
    a = self.d[obj]
        ~~~~~~^^^^^
KeyError: 'ssi_odoo_demo'

During handling of the above exception, another exception occurred:

Traceback (most recent call last):
  File "D:\work-project\ssi\odoo_demo\odoo\odoo\tools\cache.py", line 99, in lookup
    r = d[key]
        ~^^^^^
  File "D:\work-project\ssi\odoo_demo\odoo\venv\Lib\site-packages\decorator.py", line 232, in fun
    return caller(func, *(extras + args), **kw)
           ^^^^^^^^^^^^^^^^^^^^^^^^^^^^^^^^^^^^
  File "D:\work-project\ssi\odoo_demo\odoo\odoo\tools\func.py", line 87, in locked
    return func(inst, *args, **kwargs)
           ^^^^^^^^^^^^^^^^^^^^^^^^^^^
  File "D:\work-project\ssi\odoo_demo\odoo\odoo\tools\lru.py", line 34, in __getitem__
    a = self.d[obj]
        ~~~~~~^^^^^
KeyError: ('ir.model.data', <function IrModelData._xmlid_lookup at 0x00000151A4B33920>, 'customer_map_tracking.view_customer_map_geoengine_simple')

During handling of the above exception, another exception occurred:

Traceback (most recent call last):
  File "D:\work-project\ssi\odoo_demo\odoo\odoo\tools\convert.py", line 564, in _tag_root
    f(rec)
  File "D:\work-project\ssi\odoo_demo\odoo\odoo\tools\convert.py", line 429, in _tag_record
    f_val = self.id_get(f_ref, raise_if_not_found=nodeattr2bool(rec, 'forcecreate', True))
            ^^^^^^^^^^^^^^^^^^^^^^^^^^^^^^^^^^^^^^^^^^^^^^^^^^^^^^^^^^^^^^^^^^^^^^^^^^^^^^
  File "D:\work-project\ssi\odoo_demo\odoo\odoo\tools\convert.py", line 546, in id_get
    res = self.model_id_get(id_str, raise_if_not_found)
          ^^^^^^^^^^^^^^^^^^^^^^^^^^^^^^^^^^^^^^^^^^^^^
  File "D:\work-project\ssi\odoo_demo\odoo\odoo\tools\convert.py", line 552, in model_id_get
    return self.env['ir.model.data']._xmlid_to_res_model_res_id(id_str, raise_if_not_found=raise_if_not_found)
           ^^^^^^^^^^^^^^^^^^^^^^^^^^^^^^^^^^^^^^^^^^^^^^^^^^^^^^^^^^^^^^^^^^^^^^^^^^^^^^^^^^^^^^^^^^^^^^^^^^^
  File "D:\work-project\ssi\odoo_demo\odoo\odoo\addons\base\models\ir_model.py", line 2205, in _xmlid_to_res_model_res_id
    return self._xmlid_lookup(xmlid)
           ^^^^^^^^^^^^^^^^^^^^^^^^^
  File "D:\work-project\ssi\odoo_demo\odoo\venv\Lib\site-packages\decorator.py", line 232, in fun
    return caller(func, *(extras + args), **kw)
           ^^^^^^^^^^^^^^^^^^^^^^^^^^^^^^^^^^^^
  File "D:\work-project\ssi\odoo_demo\odoo\odoo\tools\cache.py", line 104, in lookup
    value = d[key] = self.method(*args, **kwargs)
                     ^^^^^^^^^^^^^^^^^^^^^^^^^^^^
  File "D:\work-project\ssi\odoo_demo\odoo\odoo\addons\base\models\ir_model.py", line 2198, in _xmlid_lookup
    raise ValueError('External ID not found in the system: %s' % xmlid)
ValueError: External ID not found in the system: customer_map_tracking.view_customer_map_geoengine_simple

The above exception was the direct cause of the following exception:

Traceback (most recent call last):
  File "D:\work-project\ssi\odoo_demo\odoo\odoo\modules\registry.py", line 110, in new
    odoo.modules.load_modules(registry, force_demo, status, update_module)
  File "D:\work-project\ssi\odoo_demo\odoo\odoo\modules\loading.py", line 481, in load_modules
    processed_modules += load_marked_modules(env, graph,
                         ^^^^^^^^^^^^^^^^^^^^^^^^^^^^^^^
  File "D:\work-project\ssi\odoo_demo\odoo\odoo\modules\loading.py", line 366, in load_marked_modules
    loaded, processed = load_module_graph(
                        ^^^^^^^^^^^^^^^^^^
  File "D:\work-project\ssi\odoo_demo\odoo\odoo\modules\loading.py", line 229, in load_module_graph
    load_data(env, idref, mode, kind='data', package=package)
  File "D:\work-project\ssi\odoo_demo\odoo\odoo\modules\loading.py", line 73, in load_data
    tools.convert_file(env, package.name, filename, idref, mode, noupdate, kind)
  File "D:\work-project\ssi\odoo_demo\odoo\odoo\tools\convert.py", line 635, in convert_file
    convert_xml_import(env, module, fp, idref, mode, noupdate)
  File "D:\work-project\ssi\odoo_demo\odoo\odoo\tools\convert.py", line 701, in convert_xml_import
    obj.parse(doc.getroot())
  File "D:\work-project\ssi\odoo_demo\odoo\odoo\tools\convert.py", line 621, in parse
    self._tag_root(de)
  File "D:\work-project\ssi\odoo_demo\odoo\odoo\tools\convert.py", line 564, in _tag_root
    f(rec)
  File "D:\work-project\ssi\odoo_demo\odoo\odoo\tools\convert.py", line 577, in _tag_root
    raise ParseError('while parsing %s:%s, somewhere inside\n%s' % (
odoo.tools.convert.ParseError: while parsing file:/d:/work-project/ssi/odoo_demo/odoo/custom_addons/customer_map_tracking/views/customer_map_actions.xml:5, somewhere inside
<record id="action_customer_map_dashboard" model="ir.actions.act_window">
            <field name="name">Map Dashboard</field>
            <field name="res_model">customer.map</field>
            <field name="view_mode">geoengine,tree,form</field>
            <field name="view_id" ref="view_customer_map_geoengine_simple"/>
            <field name="domain">[('active', '=', True), ('shape', '!=', False)]</field>
            <field name="context">{
                'create': True,
                'edit': True,
                'delete': False
            }</field>
        </record>
2025-09-27 10:02:34,541 13768 ERROR ? odoo.http: Exception during request handling. 
Traceback (most recent call last):
  File "D:\work-project\ssi\odoo_demo\odoo\odoo\modules\registry.py", line 87, in __new__
    return cls.registries[db_name]
           ~~~~~~~~~~~~~~^^^^^^^^^
  File "D:\work-project\ssi\odoo_demo\odoo\venv\Lib\site-packages\decorator.py", line 232, in fun
    return caller(func, *(extras + args), **kw)
           ^^^^^^^^^^^^^^^^^^^^^^^^^^^^^^^^^^^^
  File "D:\work-project\ssi\odoo_demo\odoo\odoo\tools\func.py", line 87, in locked
    return func(inst, *args, **kwargs)
           ^^^^^^^^^^^^^^^^^^^^^^^^^^^
  File "D:\work-project\ssi\odoo_demo\odoo\odoo\tools\lru.py", line 34, in __getitem__
    a = self.d[obj]
        ~~~~~~^^^^^
KeyError: 'ssi_odoo_demo'

During handling of the above exception, another exception occurred:

Traceback (most recent call last):
  File "D:\work-project\ssi\odoo_demo\odoo\odoo\tools\cache.py", line 99, in lookup
    r = d[key]
        ~^^^^^
  File "D:\work-project\ssi\odoo_demo\odoo\venv\Lib\site-packages\decorator.py", line 232, in fun
    return caller(func, *(extras + args), **kw)
           ^^^^^^^^^^^^^^^^^^^^^^^^^^^^^^^^^^^^
  File "D:\work-project\ssi\odoo_demo\odoo\odoo\tools\func.py", line 87, in locked
    return func(inst, *args, **kwargs)
           ^^^^^^^^^^^^^^^^^^^^^^^^^^^
  File "D:\work-project\ssi\odoo_demo\odoo\odoo\tools\lru.py", line 34, in __getitem__
    a = self.d[obj]
        ~~~~~~^^^^^
KeyError: ('ir.model.data', <function IrModelData._xmlid_lookup at 0x00000151A4B33920>, 'customer_map_tracking.view_customer_map_geoengine_simple')

During handling of the above exception, another exception occurred:

Traceback (most recent call last):
  File "D:\work-project\ssi\odoo_demo\odoo\odoo\tools\convert.py", line 564, in _tag_root
    f(rec)
  File "D:\work-project\ssi\odoo_demo\odoo\odoo\tools\convert.py", line 429, in _tag_record
    f_val = self.id_get(f_ref, raise_if_not_found=nodeattr2bool(rec, 'forcecreate', True))
            ^^^^^^^^^^^^^^^^^^^^^^^^^^^^^^^^^^^^^^^^^^^^^^^^^^^^^^^^^^^^^^^^^^^^^^^^^^^^^^
  File "D:\work-project\ssi\odoo_demo\odoo\odoo\tools\convert.py", line 546, in id_get
    res = self.model_id_get(id_str, raise_if_not_found)
          ^^^^^^^^^^^^^^^^^^^^^^^^^^^^^^^^^^^^^^^^^^^^^
  File "D:\work-project\ssi\odoo_demo\odoo\odoo\tools\convert.py", line 552, in model_id_get
    return self.env['ir.model.data']._xmlid_to_res_model_res_id(id_str, raise_if_not_found=raise_if_not_found)
           ^^^^^^^^^^^^^^^^^^^^^^^^^^^^^^^^^^^^^^^^^^^^^^^^^^^^^^^^^^^^^^^^^^^^^^^^^^^^^^^^^^^^^^^^^^^^^^^^^^^
  File "D:\work-project\ssi\odoo_demo\odoo\odoo\addons\base\models\ir_model.py", line 2205, in _xmlid_to_res_model_res_id
    return self._xmlid_lookup(xmlid)
           ^^^^^^^^^^^^^^^^^^^^^^^^^
  File "D:\work-project\ssi\odoo_demo\odoo\venv\Lib\site-packages\decorator.py", line 232, in fun
    return caller(func, *(extras + args), **kw)
           ^^^^^^^^^^^^^^^^^^^^^^^^^^^^^^^^^^^^
  File "D:\work-project\ssi\odoo_demo\odoo\odoo\tools\cache.py", line 104, in lookup
    value = d[key] = self.method(*args, **kwargs)
                     ^^^^^^^^^^^^^^^^^^^^^^^^^^^^
  File "D:\work-project\ssi\odoo_demo\odoo\odoo\addons\base\models\ir_model.py", line 2198, in _xmlid_lookup
    raise ValueError('External ID not found in the system: %s' % xmlid)
ValueError: External ID not found in the system: customer_map_tracking.view_customer_map_geoengine_simple

The above exception was the direct cause of the following exception:

Traceback (most recent call last):
  File "D:\work-project\ssi\odoo_demo\odoo\odoo\http.py", line 2396, in __call__
    response = request._serve_db()
               ^^^^^^^^^^^^^^^^^^^
  File "D:\work-project\ssi\odoo_demo\odoo\odoo\http.py", line 1949, in _serve_db
    self.registry = Registry(self.db).check_signaling()
                    ^^^^^^^^^^^^^^^^^
  File "D:\work-project\ssi\odoo_demo\odoo\odoo\modules\registry.py", line 89, in __new__
    return cls.new(db_name)
           ^^^^^^^^^^^^^^^^
  File "D:\work-project\ssi\odoo_demo\odoo\venv\Lib\site-packages\decorator.py", line 232, in fun
    return caller(func, *(extras + args), **kw)
           ^^^^^^^^^^^^^^^^^^^^^^^^^^^^^^^^^^^^
  File "D:\work-project\ssi\odoo_demo\odoo\odoo\tools\func.py", line 87, in locked
    return func(inst, *args, **kwargs)
           ^^^^^^^^^^^^^^^^^^^^^^^^^^^
  File "D:\work-project\ssi\odoo_demo\odoo\odoo\modules\registry.py", line 110, in new
    odoo.modules.load_modules(registry, force_demo, status, update_module)
  File "D:\work-project\ssi\odoo_demo\odoo\odoo\modules\loading.py", line 481, in load_modules
    processed_modules += load_marked_modules(env, graph,
                         ^^^^^^^^^^^^^^^^^^^^^^^^^^^^^^^
  File "D:\work-project\ssi\odoo_demo\odoo\odoo\modules\loading.py", line 366, in load_marked_modules
    loaded, processed = load_module_graph(
                        ^^^^^^^^^^^^^^^^^^
  File "D:\work-project\ssi\odoo_demo\odoo\odoo\modules\loading.py", line 229, in load_module_graph
    load_data(env, idref, mode, kind='data', package=package)
  File "D:\work-project\ssi\odoo_demo\odoo\odoo\modules\loading.py", line 73, in load_data
    tools.convert_file(env, package.name, filename, idref, mode, noupdate, kind)
  File "D:\work-project\ssi\odoo_demo\odoo\odoo\tools\convert.py", line 635, in convert_file
    convert_xml_import(env, module, fp, idref, mode, noupdate)
  File "D:\work-project\ssi\odoo_demo\odoo\odoo\tools\convert.py", line 701, in convert_xml_import
    obj.parse(doc.getroot())
  File "D:\work-project\ssi\odoo_demo\odoo\odoo\tools\convert.py", line 621, in parse
    self._tag_root(de)
  File "D:\work-project\ssi\odoo_demo\odoo\odoo\tools\convert.py", line 564, in _tag_root
    f(rec)
  File "D:\work-project\ssi\odoo_demo\odoo\odoo\tools\convert.py", line 577, in _tag_root
    raise ParseError('while parsing %s:%s, somewhere inside\n%s' % (
odoo.tools.convert.ParseError: while parsing file:/d:/work-project/ssi/odoo_demo/odoo/custom_addons/customer_map_tracking/views/customer_map_actions.xml:5, somewhere inside
<record id="action_customer_map_dashboard" model="ir.actions.act_window">
            <field name="name">Map Dashboard</field>
            <field name="res_model">customer.map</field>
            <field name="view_mode">geoengine,tree,form</field>
            <field name="view_id" ref="view_customer_map_geoengine_simple"/>
            <field name="domain">[('active', '=', True), ('shape', '!=', False)]</field>
            <field name="context">{
                'create': True,
                'edit': True,
                'delete': False
            }</field>
        </record>
2025-09-27 10:02:34,541 13768 INFO ? werkzeug: 127.0.0.1 - - [27/Sep/2025 10:02:34] "GET /web HTTP/1.1" 500 - 193 0.088 0.242
2025-09-27 10:02:34,578 13768 INFO ? odoo.modules.loading: loading 1 modules... 
2025-09-27 10:02:34,586 13768 INFO ? odoo.modules.loading: 1 modules loaded in 0.01s, 0 queries (+0 extra) 
2025-09-27 10:02:34,593 13768 INFO ? odoo.modules.loading: loading 77 modules... 
2025-09-27 10:02:34,613 13768 INFO ? odoo.modules.loading: Loading module customer_map_tracking (28/77) 
2025-09-27 10:02:34,696 13768 INFO ? odoo.modules.registry: module customer_map_tracking: creating or updating database tables 
2025-09-27 10:02:34,706 13768 WARNING ? odoo.addons.base.models.ir_model: Two fields (location_display, shape) of customer.map() have the same label: Location. [Modules: customer_map_tracking and customer_map_tracking] 
2025-09-27 10:02:34,725 13768 INFO ? odoo.modules.loading: loading customer_map_tracking/security/security.xml 
2025-09-27 10:02:34,787 13768 INFO ? odoo.modules.loading: loading customer_map_tracking/security/ir.model.access.csv 
2025-09-27 10:02:34,797 13768 INFO ? odoo.modules.loading: loading customer_map_tracking/views/customer_map_views.xml 
2025-09-27 10:02:34,813 13768 WARNING ? odoo.addons.base.models.ir_ui_view: set_location_from_coordinates on customer.map has parameters and cannot be called from a button
View error context:
{'file': 'd:\\work-project\\ssi\\odoo_demo\\odoo\\custom_addons\\customer_map_tracking\\views\\customer_map_views.xml',
 'line': 59,
 'name': 'customer.map.form',
 'view': ir.ui.view(1314,),
 'view.model': 'customer.map',
 'view.parent': ir.ui.view(),
 'xmlid': 'view_customer_map_form'} 
2025-09-27 10:02:34,823 13768 INFO ? odoo.modules.loading: loading customer_map_tracking/views/customer_map_geoengine_views.xml 
2025-09-27 10:02:34,843 13768 INFO ? odoo.modules.loading: loading customer_map_tracking/views/customer_map_actions.xml 
2025-09-27 10:02:34,847 13768 WARNING ? odoo.modules.loading: Transient module states were reset 
2025-09-27 10:02:34,847 13768 ERROR ? odoo.modules.registry: Failed to load registry 
Traceback (most recent call last):
  File "D:\work-project\ssi\odoo_demo\odoo\odoo\modules\registry.py", line 87, in __new__
    return cls.registries[db_name]
           ~~~~~~~~~~~~~~^^^^^^^^^
  File "D:\work-project\ssi\odoo_demo\odoo\venv\Lib\site-packages\decorator.py", line 232, in fun
    return caller(func, *(extras + args), **kw)
           ^^^^^^^^^^^^^^^^^^^^^^^^^^^^^^^^^^^^
  File "D:\work-project\ssi\odoo_demo\odoo\odoo\tools\func.py", line 87, in locked
    return func(inst, *args, **kwargs)
           ^^^^^^^^^^^^^^^^^^^^^^^^^^^
  File "D:\work-project\ssi\odoo_demo\odoo\odoo\tools\lru.py", line 34, in __getitem__
    a = self.d[obj]
        ~~~~~~^^^^^
KeyError: 'ssi_odoo_demo'

During handling of the above exception, another exception occurred:

Traceback (most recent call last):
  File "D:\work-project\ssi\odoo_demo\odoo\odoo\tools\cache.py", line 99, in lookup
    r = d[key]
        ~^^^^^
  File "D:\work-project\ssi\odoo_demo\odoo\venv\Lib\site-packages\decorator.py", line 232, in fun
    return caller(func, *(extras + args), **kw)
           ^^^^^^^^^^^^^^^^^^^^^^^^^^^^^^^^^^^^
  File "D:\work-project\ssi\odoo_demo\odoo\odoo\tools\func.py", line 87, in locked
    return func(inst, *args, **kwargs)
           ^^^^^^^^^^^^^^^^^^^^^^^^^^^
  File "D:\work-project\ssi\odoo_demo\odoo\odoo\tools\lru.py", line 34, in __getitem__
    a = self.d[obj]
        ~~~~~~^^^^^
KeyError: ('ir.model.data', <function IrModelData._xmlid_lookup at 0x00000151A4B33920>, 'customer_map_tracking.view_customer_map_geoengine_simple')

During handling of the above exception, another exception occurred:

Traceback (most recent call last):
  File "D:\work-project\ssi\odoo_demo\odoo\odoo\tools\convert.py", line 564, in _tag_root
    f(rec)
  File "D:\work-project\ssi\odoo_demo\odoo\odoo\tools\convert.py", line 429, in _tag_record
    f_val = self.id_get(f_ref, raise_if_not_found=nodeattr2bool(rec, 'forcecreate', True))
            ^^^^^^^^^^^^^^^^^^^^^^^^^^^^^^^^^^^^^^^^^^^^^^^^^^^^^^^^^^^^^^^^^^^^^^^^^^^^^^
  File "D:\work-project\ssi\odoo_demo\odoo\odoo\tools\convert.py", line 546, in id_get
    res = self.model_id_get(id_str, raise_if_not_found)
          ^^^^^^^^^^^^^^^^^^^^^^^^^^^^^^^^^^^^^^^^^^^^^
  File "D:\work-project\ssi\odoo_demo\odoo\odoo\tools\convert.py", line 552, in model_id_get
    return self.env['ir.model.data']._xmlid_to_res_model_res_id(id_str, raise_if_not_found=raise_if_not_found)
           ^^^^^^^^^^^^^^^^^^^^^^^^^^^^^^^^^^^^^^^^^^^^^^^^^^^^^^^^^^^^^^^^^^^^^^^^^^^^^^^^^^^^^^^^^^^^^^^^^^^
  File "D:\work-project\ssi\odoo_demo\odoo\odoo\addons\base\models\ir_model.py", line 2205, in _xmlid_to_res_model_res_id
    return self._xmlid_lookup(xmlid)
           ^^^^^^^^^^^^^^^^^^^^^^^^^
  File "D:\work-project\ssi\odoo_demo\odoo\venv\Lib\site-packages\decorator.py", line 232, in fun
    return caller(func, *(extras + args), **kw)
           ^^^^^^^^^^^^^^^^^^^^^^^^^^^^^^^^^^^^
  File "D:\work-project\ssi\odoo_demo\odoo\odoo\tools\cache.py", line 104, in lookup
    value = d[key] = self.method(*args, **kwargs)
                     ^^^^^^^^^^^^^^^^^^^^^^^^^^^^
  File "D:\work-project\ssi\odoo_demo\odoo\odoo\addons\base\models\ir_model.py", line 2198, in _xmlid_lookup
    raise ValueError('External ID not found in the system: %s' % xmlid)
ValueError: External ID not found in the system: customer_map_tracking.view_customer_map_geoengine_simple

The above exception was the direct cause of the following exception:

Traceback (most recent call last):
  File "D:\work-project\ssi\odoo_demo\odoo\odoo\modules\registry.py", line 110, in new
    odoo.modules.load_modules(registry, force_demo, status, update_module)
  File "D:\work-project\ssi\odoo_demo\odoo\odoo\modules\loading.py", line 481, in load_modules
    processed_modules += load_marked_modules(env, graph,
                         ^^^^^^^^^^^^^^^^^^^^^^^^^^^^^^^
  File "D:\work-project\ssi\odoo_demo\odoo\odoo\modules\loading.py", line 366, in load_marked_modules
    loaded, processed = load_module_graph(
                        ^^^^^^^^^^^^^^^^^^
  File "D:\work-project\ssi\odoo_demo\odoo\odoo\modules\loading.py", line 229, in load_module_graph
    load_data(env, idref, mode, kind='data', package=package)
  File "D:\work-project\ssi\odoo_demo\odoo\odoo\modules\loading.py", line 73, in load_data
    tools.convert_file(env, package.name, filename, idref, mode, noupdate, kind)
  File "D:\work-project\ssi\odoo_demo\odoo\odoo\tools\convert.py", line 635, in convert_file
    convert_xml_import(env, module, fp, idref, mode, noupdate)
  File "D:\work-project\ssi\odoo_demo\odoo\odoo\tools\convert.py", line 701, in convert_xml_import
    obj.parse(doc.getroot())
  File "D:\work-project\ssi\odoo_demo\odoo\odoo\tools\convert.py", line 621, in parse
    self._tag_root(de)
  File "D:\work-project\ssi\odoo_demo\odoo\odoo\tools\convert.py", line 564, in _tag_root
    f(rec)
  File "D:\work-project\ssi\odoo_demo\odoo\odoo\tools\convert.py", line 577, in _tag_root
    raise ParseError('while parsing %s:%s, somewhere inside\n%s' % (
odoo.tools.convert.ParseError: while parsing file:/d:/work-project/ssi/odoo_demo/odoo/custom_addons/customer_map_tracking/views/customer_map_actions.xml:5, somewhere inside
<record id="action_customer_map_dashboard" model="ir.actions.act_window">
            <field name="name">Map Dashboard</field>
            <field name="res_model">customer.map</field>
            <field name="view_mode">geoengine,tree,form</field>
            <field name="view_id" ref="view_customer_map_geoengine_simple"/>
            <field name="domain">[('active', '=', True), ('shape', '!=', False)]</field>
            <field name="context">{
                'create': True,
                'edit': True,
                'delete': False
            }</field>
        </record>
2025-09-27 10:02:34,847 13768 ERROR ? odoo.http: Exception during request handling. 
Traceback (most recent call last):
  File "D:\work-project\ssi\odoo_demo\odoo\odoo\modules\registry.py", line 87, in __new__
    return cls.registries[db_name]
           ~~~~~~~~~~~~~~^^^^^^^^^
  File "D:\work-project\ssi\odoo_demo\odoo\venv\Lib\site-packages\decorator.py", line 232, in fun
    return caller(func, *(extras + args), **kw)
           ^^^^^^^^^^^^^^^^^^^^^^^^^^^^^^^^^^^^
  File "D:\work-project\ssi\odoo_demo\odoo\odoo\tools\func.py", line 87, in locked
    return func(inst, *args, **kwargs)
           ^^^^^^^^^^^^^^^^^^^^^^^^^^^
  File "D:\work-project\ssi\odoo_demo\odoo\odoo\tools\lru.py", line 34, in __getitem__
    a = self.d[obj]
        ~~~~~~^^^^^
KeyError: 'ssi_odoo_demo'

During handling of the above exception, another exception occurred:

Traceback (most recent call last):
  File "D:\work-project\ssi\odoo_demo\odoo\odoo\tools\cache.py", line 99, in lookup
    r = d[key]
        ~^^^^^
  File "D:\work-project\ssi\odoo_demo\odoo\venv\Lib\site-packages\decorator.py", line 232, in fun
    return caller(func, *(extras + args), **kw)
           ^^^^^^^^^^^^^^^^^^^^^^^^^^^^^^^^^^^^
  File "D:\work-project\ssi\odoo_demo\odoo\odoo\tools\func.py", line 87, in locked
    return func(inst, *args, **kwargs)
           ^^^^^^^^^^^^^^^^^^^^^^^^^^^
  File "D:\work-project\ssi\odoo_demo\odoo\odoo\tools\lru.py", line 34, in __getitem__
    a = self.d[obj]
        ~~~~~~^^^^^
KeyError: ('ir.model.data', <function IrModelData._xmlid_lookup at 0x00000151A4B33920>, 'customer_map_tracking.view_customer_map_geoengine_simple')

During handling of the above exception, another exception occurred:

Traceback (most recent call last):
  File "D:\work-project\ssi\odoo_demo\odoo\odoo\tools\convert.py", line 564, in _tag_root
    f(rec)
  File "D:\work-project\ssi\odoo_demo\odoo\odoo\tools\convert.py", line 429, in _tag_record
    f_val = self.id_get(f_ref, raise_if_not_found=nodeattr2bool(rec, 'forcecreate', True))
            ^^^^^^^^^^^^^^^^^^^^^^^^^^^^^^^^^^^^^^^^^^^^^^^^^^^^^^^^^^^^^^^^^^^^^^^^^^^^^^
  File "D:\work-project\ssi\odoo_demo\odoo\odoo\tools\convert.py", line 546, in id_get
    res = self.model_id_get(id_str, raise_if_not_found)
          ^^^^^^^^^^^^^^^^^^^^^^^^^^^^^^^^^^^^^^^^^^^^^
  File "D:\work-project\ssi\odoo_demo\odoo\odoo\tools\convert.py", line 552, in model_id_get
    return self.env['ir.model.data']._xmlid_to_res_model_res_id(id_str, raise_if_not_found=raise_if_not_found)
           ^^^^^^^^^^^^^^^^^^^^^^^^^^^^^^^^^^^^^^^^^^^^^^^^^^^^^^^^^^^^^^^^^^^^^^^^^^^^^^^^^^^^^^^^^^^^^^^^^^^
  File "D:\work-project\ssi\odoo_demo\odoo\odoo\addons\base\models\ir_model.py", line 2205, in _xmlid_to_res_model_res_id
    return self._xmlid_lookup(xmlid)
           ^^^^^^^^^^^^^^^^^^^^^^^^^
  File "D:\work-project\ssi\odoo_demo\odoo\venv\Lib\site-packages\decorator.py", line 232, in fun
    return caller(func, *(extras + args), **kw)
           ^^^^^^^^^^^^^^^^^^^^^^^^^^^^^^^^^^^^
  File "D:\work-project\ssi\odoo_demo\odoo\odoo\tools\cache.py", line 104, in lookup
    value = d[key] = self.method(*args, **kwargs)
                     ^^^^^^^^^^^^^^^^^^^^^^^^^^^^
  File "D:\work-project\ssi\odoo_demo\odoo\odoo\addons\base\models\ir_model.py", line 2198, in _xmlid_lookup
    raise ValueError('External ID not found in the system: %s' % xmlid)
ValueError: External ID not found in the system: customer_map_tracking.view_customer_map_geoengine_simple

The above exception was the direct cause of the following exception:

Traceback (most recent call last):
  File "D:\work-project\ssi\odoo_demo\odoo\odoo\http.py", line 2396, in __call__
    response = request._serve_db()
               ^^^^^^^^^^^^^^^^^^^
  File "D:\work-project\ssi\odoo_demo\odoo\odoo\http.py", line 1949, in _serve_db
    self.registry = Registry(self.db).check_signaling()
                    ^^^^^^^^^^^^^^^^^
  File "D:\work-project\ssi\odoo_demo\odoo\odoo\modules\registry.py", line 89, in __new__
    return cls.new(db_name)
           ^^^^^^^^^^^^^^^^
  File "D:\work-project\ssi\odoo_demo\odoo\venv\Lib\site-packages\decorator.py", line 232, in fun
    return caller(func, *(extras + args), **kw)
           ^^^^^^^^^^^^^^^^^^^^^^^^^^^^^^^^^^^^
  File "D:\work-project\ssi\odoo_demo\odoo\odoo\tools\func.py", line 87, in locked
    return func(inst, *args, **kwargs)
           ^^^^^^^^^^^^^^^^^^^^^^^^^^^
  File "D:\work-project\ssi\odoo_demo\odoo\odoo\modules\registry.py", line 110, in new
    odoo.modules.load_modules(registry, force_demo, status, update_module)
  File "D:\work-project\ssi\odoo_demo\odoo\odoo\modules\loading.py", line 481, in load_modules
    processed_modules += load_marked_modules(env, graph,
                         ^^^^^^^^^^^^^^^^^^^^^^^^^^^^^^^
  File "D:\work-project\ssi\odoo_demo\odoo\odoo\modules\loading.py", line 366, in load_marked_modules
    loaded, processed = load_module_graph(
                        ^^^^^^^^^^^^^^^^^^
  File "D:\work-project\ssi\odoo_demo\odoo\odoo\modules\loading.py", line 229, in load_module_graph
    load_data(env, idref, mode, kind='data', package=package)
  File "D:\work-project\ssi\odoo_demo\odoo\odoo\modules\loading.py", line 73, in load_data
    tools.convert_file(env, package.name, filename, idref, mode, noupdate, kind)
  File "D:\work-project\ssi\odoo_demo\odoo\odoo\tools\convert.py", line 635, in convert_file
    convert_xml_import(env, module, fp, idref, mode, noupdate)
  File "D:\work-project\ssi\odoo_demo\odoo\odoo\tools\convert.py", line 701, in convert_xml_import
    obj.parse(doc.getroot())
  File "D:\work-project\ssi\odoo_demo\odoo\odoo\tools\convert.py", line 621, in parse
    self._tag_root(de)
  File "D:\work-project\ssi\odoo_demo\odoo\odoo\tools\convert.py", line 564, in _tag_root
    f(rec)
  File "D:\work-project\ssi\odoo_demo\odoo\odoo\tools\convert.py", line 577, in _tag_root
    raise ParseError('while parsing %s:%s, somewhere inside\n%s' % (
odoo.tools.convert.ParseError: while parsing file:/d:/work-project/ssi/odoo_demo/odoo/custom_addons/customer_map_tracking/views/customer_map_actions.xml:5, somewhere inside
<record id="action_customer_map_dashboard" model="ir.actions.act_window">
            <field name="name">Map Dashboard</field>
            <field name="res_model">customer.map</field>
            <field name="view_mode">geoengine,tree,form</field>
            <field name="view_id" ref="view_customer_map_geoengine_simple"/>
            <field name="domain">[('active', '=', True), ('shape', '!=', False)]</field>
            <field name="context">{
                'create': True,
                'edit': True,
                'delete': False
            }</field>
        </record>
2025-09-27 10:02:34,847 13768 INFO ? werkzeug: 127.0.0.1 - - [27/Sep/2025 10:02:34] "GET /favicon.ico HTTP/1.1" 500 - 193 0.102 0.176
2025-09-27 10:02:34,923 13768 INFO ? odoo.modules.loading: loading 1 modules... 
2025-09-27 10:02:34,928 13768 INFO ? odoo.modules.loading: 1 modules loaded in 0.00s, 0 queries (+0 extra) 
2025-09-27 10:02:34,941 13768 INFO ? odoo.modules.loading: loading 77 modules... 
2025-09-27 10:02:34,960 13768 INFO ? odoo.modules.loading: Loading module customer_map_tracking (28/77) 
2025-09-27 10:02:35,030 13768 INFO ? odoo.modules.registry: module customer_map_tracking: creating or updating database tables 
2025-09-27 10:02:35,038 13768 WARNING ? odoo.addons.base.models.ir_model: Two fields (location_display, shape) of customer.map() have the same label: Location. [Modules: customer_map_tracking and customer_map_tracking] 
2025-09-27 10:02:35,055 13768 INFO ? odoo.modules.loading: loading customer_map_tracking/security/security.xml 
2025-09-27 10:02:35,114 13768 INFO ? odoo.modules.loading: loading customer_map_tracking/security/ir.model.access.csv 
2025-09-27 10:02:35,124 13768 INFO ? odoo.modules.loading: loading customer_map_tracking/views/customer_map_views.xml 
2025-09-27 10:02:35,137 13768 WARNING ? odoo.addons.base.models.ir_ui_view: set_location_from_coordinates on customer.map has parameters and cannot be called from a button
View error context:
{'file': 'd:\\work-project\\ssi\\odoo_demo\\odoo\\custom_addons\\customer_map_tracking\\views\\customer_map_views.xml',
 'line': 59,
 'name': 'customer.map.form',
 'view': ir.ui.view(1314,),
 'view.model': 'customer.map',
 'view.parent': ir.ui.view(),
 'xmlid': 'view_customer_map_form'} 
2025-09-27 10:02:35,147 13768 INFO ? odoo.modules.loading: loading customer_map_tracking/views/customer_map_geoengine_views.xml 
2025-09-27 10:02:35,167 13768 INFO ? odoo.modules.loading: loading customer_map_tracking/views/customer_map_actions.xml 
2025-09-27 10:02:35,172 13768 WARNING ? odoo.modules.loading: Transient module states were reset 
2025-09-27 10:02:35,172 13768 ERROR ? odoo.modules.registry: Failed to load registry 
Traceback (most recent call last):
  File "D:\work-project\ssi\odoo_demo\odoo\odoo\modules\registry.py", line 87, in __new__
    return cls.registries[db_name]
           ~~~~~~~~~~~~~~^^^^^^^^^
  File "D:\work-project\ssi\odoo_demo\odoo\venv\Lib\site-packages\decorator.py", line 232, in fun
    return caller(func, *(extras + args), **kw)
           ^^^^^^^^^^^^^^^^^^^^^^^^^^^^^^^^^^^^
  File "D:\work-project\ssi\odoo_demo\odoo\odoo\tools\func.py", line 87, in locked
    return func(inst, *args, **kwargs)
           ^^^^^^^^^^^^^^^^^^^^^^^^^^^
  File "D:\work-project\ssi\odoo_demo\odoo\odoo\tools\lru.py", line 34, in __getitem__
    a = self.d[obj]
        ~~~~~~^^^^^
KeyError: 'ssi_odoo_demo'

During handling of the above exception, another exception occurred:

Traceback (most recent call last):
  File "D:\work-project\ssi\odoo_demo\odoo\odoo\tools\cache.py", line 99, in lookup
    r = d[key]
        ~^^^^^
  File "D:\work-project\ssi\odoo_demo\odoo\venv\Lib\site-packages\decorator.py", line 232, in fun
    return caller(func, *(extras + args), **kw)
           ^^^^^^^^^^^^^^^^^^^^^^^^^^^^^^^^^^^^
  File "D:\work-project\ssi\odoo_demo\odoo\odoo\tools\func.py", line 87, in locked
    return func(inst, *args, **kwargs)
           ^^^^^^^^^^^^^^^^^^^^^^^^^^^
  File "D:\work-project\ssi\odoo_demo\odoo\odoo\tools\lru.py", line 34, in __getitem__
    a = self.d[obj]
        ~~~~~~^^^^^
KeyError: ('ir.model.data', <function IrModelData._xmlid_lookup at 0x00000151A4B33920>, 'customer_map_tracking.view_customer_map_geoengine_simple')

During handling of the above exception, another exception occurred:

Traceback (most recent call last):
  File "D:\work-project\ssi\odoo_demo\odoo\odoo\tools\convert.py", line 564, in _tag_root
    f(rec)
  File "D:\work-project\ssi\odoo_demo\odoo\odoo\tools\convert.py", line 429, in _tag_record
    f_val = self.id_get(f_ref, raise_if_not_found=nodeattr2bool(rec, 'forcecreate', True))
            ^^^^^^^^^^^^^^^^^^^^^^^^^^^^^^^^^^^^^^^^^^^^^^^^^^^^^^^^^^^^^^^^^^^^^^^^^^^^^^
  File "D:\work-project\ssi\odoo_demo\odoo\odoo\tools\convert.py", line 546, in id_get
    res = self.model_id_get(id_str, raise_if_not_found)
          ^^^^^^^^^^^^^^^^^^^^^^^^^^^^^^^^^^^^^^^^^^^^^
  File "D:\work-project\ssi\odoo_demo\odoo\odoo\tools\convert.py", line 552, in model_id_get
    return self.env['ir.model.data']._xmlid_to_res_model_res_id(id_str, raise_if_not_found=raise_if_not_found)
           ^^^^^^^^^^^^^^^^^^^^^^^^^^^^^^^^^^^^^^^^^^^^^^^^^^^^^^^^^^^^^^^^^^^^^^^^^^^^^^^^^^^^^^^^^^^^^^^^^^^
  File "D:\work-project\ssi\odoo_demo\odoo\odoo\addons\base\models\ir_model.py", line 2205, in _xmlid_to_res_model_res_id
    return self._xmlid_lookup(xmlid)
           ^^^^^^^^^^^^^^^^^^^^^^^^^
  File "D:\work-project\ssi\odoo_demo\odoo\venv\Lib\site-packages\decorator.py", line 232, in fun
    return caller(func, *(extras + args), **kw)
           ^^^^^^^^^^^^^^^^^^^^^^^^^^^^^^^^^^^^
  File "D:\work-project\ssi\odoo_demo\odoo\odoo\tools\cache.py", line 104, in lookup
    value = d[key] = self.method(*args, **kwargs)
                     ^^^^^^^^^^^^^^^^^^^^^^^^^^^^
  File "D:\work-project\ssi\odoo_demo\odoo\odoo\addons\base\models\ir_model.py", line 2198, in _xmlid_lookup
    raise ValueError('External ID not found in the system: %s' % xmlid)
ValueError: External ID not found in the system: customer_map_tracking.view_customer_map_geoengine_simple

The above exception was the direct cause of the following exception:

Traceback (most recent call last):
  File "D:\work-project\ssi\odoo_demo\odoo\odoo\modules\registry.py", line 110, in new
    odoo.modules.load_modules(registry, force_demo, status, update_module)
  File "D:\work-project\ssi\odoo_demo\odoo\odoo\modules\loading.py", line 481, in load_modules
    processed_modules += load_marked_modules(env, graph,
                         ^^^^^^^^^^^^^^^^^^^^^^^^^^^^^^^
  File "D:\work-project\ssi\odoo_demo\odoo\odoo\modules\loading.py", line 366, in load_marked_modules
    loaded, processed = load_module_graph(
                        ^^^^^^^^^^^^^^^^^^
  File "D:\work-project\ssi\odoo_demo\odoo\odoo\modules\loading.py", line 229, in load_module_graph
    load_data(env, idref, mode, kind='data', package=package)
  File "D:\work-project\ssi\odoo_demo\odoo\odoo\modules\loading.py", line 73, in load_data
    tools.convert_file(env, package.name, filename, idref, mode, noupdate, kind)
  File "D:\work-project\ssi\odoo_demo\odoo\odoo\tools\convert.py", line 635, in convert_file
    convert_xml_import(env, module, fp, idref, mode, noupdate)
  File "D:\work-project\ssi\odoo_demo\odoo\odoo\tools\convert.py", line 701, in convert_xml_import
    obj.parse(doc.getroot())
  File "D:\work-project\ssi\odoo_demo\odoo\odoo\tools\convert.py", line 621, in parse
    self._tag_root(de)
  File "D:\work-project\ssi\odoo_demo\odoo\odoo\tools\convert.py", line 564, in _tag_root
    f(rec)
  File "D:\work-project\ssi\odoo_demo\odoo\odoo\tools\convert.py", line 577, in _tag_root
    raise ParseError('while parsing %s:%s, somewhere inside\n%s' % (
odoo.tools.convert.ParseError: while parsing file:/d:/work-project/ssi/odoo_demo/odoo/custom_addons/customer_map_tracking/views/customer_map_actions.xml:5, somewhere inside
<record id="action_customer_map_dashboard" model="ir.actions.act_window">
            <field name="name">Map Dashboard</field>
            <field name="res_model">customer.map</field>
            <field name="view_mode">geoengine,tree,form</field>
            <field name="view_id" ref="view_customer_map_geoengine_simple"/>
            <field name="domain">[('active', '=', True), ('shape', '!=', False)]</field>
            <field name="context">{
                'create': True,
                'edit': True,
                'delete': False
            }</field>
        </record>
2025-09-27 10:02:35,174 13768 ERROR ? odoo.http: Exception during request handling. 
Traceback (most recent call last):
  File "D:\work-project\ssi\odoo_demo\odoo\odoo\modules\registry.py", line 87, in __new__
    return cls.registries[db_name]
           ~~~~~~~~~~~~~~^^^^^^^^^
  File "D:\work-project\ssi\odoo_demo\odoo\venv\Lib\site-packages\decorator.py", line 232, in fun
    return caller(func, *(extras + args), **kw)
           ^^^^^^^^^^^^^^^^^^^^^^^^^^^^^^^^^^^^
  File "D:\work-project\ssi\odoo_demo\odoo\odoo\tools\func.py", line 87, in locked
    return func(inst, *args, **kwargs)
           ^^^^^^^^^^^^^^^^^^^^^^^^^^^
  File "D:\work-project\ssi\odoo_demo\odoo\odoo\tools\lru.py", line 34, in __getitem__
    a = self.d[obj]
        ~~~~~~^^^^^
KeyError: 'ssi_odoo_demo'

During handling of the above exception, another exception occurred:

Traceback (most recent call last):
  File "D:\work-project\ssi\odoo_demo\odoo\odoo\tools\cache.py", line 99, in lookup
    r = d[key]
        ~^^^^^
  File "D:\work-project\ssi\odoo_demo\odoo\venv\Lib\site-packages\decorator.py", line 232, in fun
    return caller(func, *(extras + args), **kw)
           ^^^^^^^^^^^^^^^^^^^^^^^^^^^^^^^^^^^^
  File "D:\work-project\ssi\odoo_demo\odoo\odoo\tools\func.py", line 87, in locked
    return func(inst, *args, **kwargs)
           ^^^^^^^^^^^^^^^^^^^^^^^^^^^
  File "D:\work-project\ssi\odoo_demo\odoo\odoo\tools\lru.py", line 34, in __getitem__
    a = self.d[obj]
        ~~~~~~^^^^^
KeyError: ('ir.model.data', <function IrModelData._xmlid_lookup at 0x00000151A4B33920>, 'customer_map_tracking.view_customer_map_geoengine_simple')

During handling of the above exception, another exception occurred:

Traceback (most recent call last):
  File "D:\work-project\ssi\odoo_demo\odoo\odoo\tools\convert.py", line 564, in _tag_root
    f(rec)
  File "D:\work-project\ssi\odoo_demo\odoo\odoo\tools\convert.py", line 429, in _tag_record
    f_val = self.id_get(f_ref, raise_if_not_found=nodeattr2bool(rec, 'forcecreate', True))
            ^^^^^^^^^^^^^^^^^^^^^^^^^^^^^^^^^^^^^^^^^^^^^^^^^^^^^^^^^^^^^^^^^^^^^^^^^^^^^^
  File "D:\work-project\ssi\odoo_demo\odoo\odoo\tools\convert.py", line 546, in id_get
    res = self.model_id_get(id_str, raise_if_not_found)
          ^^^^^^^^^^^^^^^^^^^^^^^^^^^^^^^^^^^^^^^^^^^^^
  File "D:\work-project\ssi\odoo_demo\odoo\odoo\tools\convert.py", line 552, in model_id_get
    return self.env['ir.model.data']._xmlid_to_res_model_res_id(id_str, raise_if_not_found=raise_if_not_found)
           ^^^^^^^^^^^^^^^^^^^^^^^^^^^^^^^^^^^^^^^^^^^^^^^^^^^^^^^^^^^^^^^^^^^^^^^^^^^^^^^^^^^^^^^^^^^^^^^^^^^
  File "D:\work-project\ssi\odoo_demo\odoo\odoo\addons\base\models\ir_model.py", line 2205, in _xmlid_to_res_model_res_id
    return self._xmlid_lookup(xmlid)
           ^^^^^^^^^^^^^^^^^^^^^^^^^
  File "D:\work-project\ssi\odoo_demo\odoo\venv\Lib\site-packages\decorator.py", line 232, in fun
    return caller(func, *(extras + args), **kw)
           ^^^^^^^^^^^^^^^^^^^^^^^^^^^^^^^^^^^^
  File "D:\work-project\ssi\odoo_demo\odoo\odoo\tools\cache.py", line 104, in lookup
    value = d[key] = self.method(*args, **kwargs)
                     ^^^^^^^^^^^^^^^^^^^^^^^^^^^^
  File "D:\work-project\ssi\odoo_demo\odoo\odoo\addons\base\models\ir_model.py", line 2198, in _xmlid_lookup
    raise ValueError('External ID not found in the system: %s' % xmlid)
ValueError: External ID not found in the system: customer_map_tracking.view_customer_map_geoengine_simple

The above exception was the direct cause of the following exception:

Traceback (most recent call last):
  File "D:\work-project\ssi\odoo_demo\odoo\odoo\http.py", line 2396, in __call__
    response = request._serve_db()
               ^^^^^^^^^^^^^^^^^^^
  File "D:\work-project\ssi\odoo_demo\odoo\odoo\http.py", line 1949, in _serve_db
    self.registry = Registry(self.db).check_signaling()
                    ^^^^^^^^^^^^^^^^^
  File "D:\work-project\ssi\odoo_demo\odoo\odoo\modules\registry.py", line 89, in __new__
    return cls.new(db_name)
           ^^^^^^^^^^^^^^^^
  File "D:\work-project\ssi\odoo_demo\odoo\venv\Lib\site-packages\decorator.py", line 232, in fun
    return caller(func, *(extras + args), **kw)
           ^^^^^^^^^^^^^^^^^^^^^^^^^^^^^^^^^^^^
  File "D:\work-project\ssi\odoo_demo\odoo\odoo\tools\func.py", line 87, in locked
    return func(inst, *args, **kwargs)
           ^^^^^^^^^^^^^^^^^^^^^^^^^^^
  File "D:\work-project\ssi\odoo_demo\odoo\odoo\modules\registry.py", line 110, in new
    odoo.modules.load_modules(registry, force_demo, status, update_module)
  File "D:\work-project\ssi\odoo_demo\odoo\odoo\modules\loading.py", line 481, in load_modules
    processed_modules += load_marked_modules(env, graph,
                         ^^^^^^^^^^^^^^^^^^^^^^^^^^^^^^^
  File "D:\work-project\ssi\odoo_demo\odoo\odoo\modules\loading.py", line 366, in load_marked_modules
    loaded, processed = load_module_graph(
                        ^^^^^^^^^^^^^^^^^^
  File "D:\work-project\ssi\odoo_demo\odoo\odoo\modules\loading.py", line 229, in load_module_graph
    load_data(env, idref, mode, kind='data', package=package)
  File "D:\work-project\ssi\odoo_demo\odoo\odoo\modules\loading.py", line 73, in load_data
    tools.convert_file(env, package.name, filename, idref, mode, noupdate, kind)
  File "D:\work-project\ssi\odoo_demo\odoo\odoo\tools\convert.py", line 635, in convert_file
    convert_xml_import(env, module, fp, idref, mode, noupdate)
  File "D:\work-project\ssi\odoo_demo\odoo\odoo\tools\convert.py", line 701, in convert_xml_import
    obj.parse(doc.getroot())
  File "D:\work-project\ssi\odoo_demo\odoo\odoo\tools\convert.py", line 621, in parse
    self._tag_root(de)
  File "D:\work-project\ssi\odoo_demo\odoo\odoo\tools\convert.py", line 564, in _tag_root
    f(rec)
  File "D:\work-project\ssi\odoo_demo\odoo\odoo\tools\convert.py", line 577, in _tag_root
    raise ParseError('while parsing %s:%s, somewhere inside\n%s' % (
odoo.tools.convert.ParseError: while parsing file:/d:/work-project/ssi/odoo_demo/odoo/custom_addons/customer_map_tracking/views/customer_map_actions.xml:5, somewhere inside
<record id="action_customer_map_dashboard" model="ir.actions.act_window">
            <field name="name">Map Dashboard</field>
            <field name="res_model">customer.map</field>
            <field name="view_mode">geoengine,tree,form</field>
            <field name="view_id" ref="view_customer_map_geoengine_simple"/>
            <field name="domain">[('active', '=', True), ('shape', '!=', False)]</field>
            <field name="context">{
                'create': True,
                'edit': True,
                'delete': False
            }</field>
        </record>
2025-09-27 10:02:35,178 13768 INFO ? werkzeug: 127.0.0.1 - - [27/Sep/2025 10:02:35] "GET /web/service-worker.js HTTP/1.1" 500 - 193 0.081 0.185
2025-09-27 10:02:36,477 13768 INFO ? odoo.modules.loading: loading 1 modules... 
2025-09-27 10:02:36,480 13768 INFO ? odoo.modules.loading: 1 modules loaded in 0.00s, 0 queries (+0 extra) 
2025-09-27 10:02:36,491 13768 INFO ? odoo.modules.loading: loading 77 modules... 
2025-09-27 10:02:36,516 13768 INFO ? odoo.modules.loading: Loading module customer_map_tracking (28/77) 
2025-09-27 10:02:36,626 13768 INFO ? odoo.modules.registry: module customer_map_tracking: creating or updating database tables 
2025-09-27 10:02:36,634 13768 WARNING ? odoo.addons.base.models.ir_model: Two fields (location_display, shape) of customer.map() have the same label: Location. [Modules: customer_map_tracking and customer_map_tracking] 
2025-09-27 10:02:36,661 13768 INFO ? odoo.modules.loading: loading customer_map_tracking/security/security.xml 
2025-09-27 10:02:36,709 13768 INFO ? odoo.modules.loading: loading customer_map_tracking/security/ir.model.access.csv 
2025-09-27 10:02:36,727 13768 INFO ? odoo.modules.loading: loading customer_map_tracking/views/customer_map_views.xml 
2025-09-27 10:02:36,751 13768 WARNING ? odoo.addons.base.models.ir_ui_view: set_location_from_coordinates on customer.map has parameters and cannot be called from a button
View error context:
{'file': 'd:\\work-project\\ssi\\odoo_demo\\odoo\\custom_addons\\customer_map_tracking\\views\\customer_map_views.xml',
 'line': 59,
 'name': 'customer.map.form',
 'view': ir.ui.view(1314,),
 'view.model': 'customer.map',
 'view.parent': ir.ui.view(),
 'xmlid': 'view_customer_map_form'} 
2025-09-27 10:02:36,768 13768 INFO ? odoo.modules.loading: loading customer_map_tracking/views/customer_map_geoengine_views.xml 
2025-09-27 10:02:36,791 13768 INFO ? odoo.modules.loading: loading customer_map_tracking/views/customer_map_actions.xml 
2025-09-27 10:02:36,795 13768 WARNING ? odoo.modules.loading: Transient module states were reset 
2025-09-27 10:02:36,795 13768 ERROR ? odoo.modules.registry: Failed to load registry 
Traceback (most recent call last):
  File "D:\work-project\ssi\odoo_demo\odoo\odoo\modules\registry.py", line 87, in __new__
    return cls.registries[db_name]
           ~~~~~~~~~~~~~~^^^^^^^^^
  File "D:\work-project\ssi\odoo_demo\odoo\venv\Lib\site-packages\decorator.py", line 232, in fun
    return caller(func, *(extras + args), **kw)
           ^^^^^^^^^^^^^^^^^^^^^^^^^^^^^^^^^^^^
  File "D:\work-project\ssi\odoo_demo\odoo\odoo\tools\func.py", line 87, in locked
    return func(inst, *args, **kwargs)
           ^^^^^^^^^^^^^^^^^^^^^^^^^^^
  File "D:\work-project\ssi\odoo_demo\odoo\odoo\tools\lru.py", line 34, in __getitem__
    a = self.d[obj]
        ~~~~~~^^^^^
KeyError: 'ssi_odoo_demo'

During handling of the above exception, another exception occurred:

Traceback (most recent call last):
  File "D:\work-project\ssi\odoo_demo\odoo\odoo\tools\cache.py", line 99, in lookup
    r = d[key]
        ~^^^^^
  File "D:\work-project\ssi\odoo_demo\odoo\venv\Lib\site-packages\decorator.py", line 232, in fun
    return caller(func, *(extras + args), **kw)
           ^^^^^^^^^^^^^^^^^^^^^^^^^^^^^^^^^^^^
  File "D:\work-project\ssi\odoo_demo\odoo\odoo\tools\func.py", line 87, in locked
    return func(inst, *args, **kwargs)
           ^^^^^^^^^^^^^^^^^^^^^^^^^^^
  File "D:\work-project\ssi\odoo_demo\odoo\odoo\tools\lru.py", line 34, in __getitem__
    a = self.d[obj]
        ~~~~~~^^^^^
KeyError: ('ir.model.data', <function IrModelData._xmlid_lookup at 0x00000151A4B33920>, 'customer_map_tracking.view_customer_map_geoengine_simple')

During handling of the above exception, another exception occurred:

Traceback (most recent call last):
  File "D:\work-project\ssi\odoo_demo\odoo\odoo\tools\convert.py", line 564, in _tag_root
    f(rec)
  File "D:\work-project\ssi\odoo_demo\odoo\odoo\tools\convert.py", line 429, in _tag_record
    f_val = self.id_get(f_ref, raise_if_not_found=nodeattr2bool(rec, 'forcecreate', True))
            ^^^^^^^^^^^^^^^^^^^^^^^^^^^^^^^^^^^^^^^^^^^^^^^^^^^^^^^^^^^^^^^^^^^^^^^^^^^^^^
  File "D:\work-project\ssi\odoo_demo\odoo\odoo\tools\convert.py", line 546, in id_get
    res = self.model_id_get(id_str, raise_if_not_found)
          ^^^^^^^^^^^^^^^^^^^^^^^^^^^^^^^^^^^^^^^^^^^^^
  File "D:\work-project\ssi\odoo_demo\odoo\odoo\tools\convert.py", line 552, in model_id_get
    return self.env['ir.model.data']._xmlid_to_res_model_res_id(id_str, raise_if_not_found=raise_if_not_found)
           ^^^^^^^^^^^^^^^^^^^^^^^^^^^^^^^^^^^^^^^^^^^^^^^^^^^^^^^^^^^^^^^^^^^^^^^^^^^^^^^^^^^^^^^^^^^^^^^^^^^
  File "D:\work-project\ssi\odoo_demo\odoo\odoo\addons\base\models\ir_model.py", line 2205, in _xmlid_to_res_model_res_id
    return self._xmlid_lookup(xmlid)
           ^^^^^^^^^^^^^^^^^^^^^^^^^
  File "D:\work-project\ssi\odoo_demo\odoo\venv\Lib\site-packages\decorator.py", line 232, in fun
    return caller(func, *(extras + args), **kw)
           ^^^^^^^^^^^^^^^^^^^^^^^^^^^^^^^^^^^^
  File "D:\work-project\ssi\odoo_demo\odoo\odoo\tools\cache.py", line 104, in lookup
    value = d[key] = self.method(*args, **kwargs)
                     ^^^^^^^^^^^^^^^^^^^^^^^^^^^^
  File "D:\work-project\ssi\odoo_demo\odoo\odoo\addons\base\models\ir_model.py", line 2198, in _xmlid_lookup
    raise ValueError('External ID not found in the system: %s' % xmlid)
ValueError: External ID not found in the system: customer_map_tracking.view_customer_map_geoengine_simple

The above exception was the direct cause of the following exception:

Traceback (most recent call last):
  File "D:\work-project\ssi\odoo_demo\odoo\odoo\modules\registry.py", line 110, in new
    odoo.modules.load_modules(registry, force_demo, status, update_module)
  File "D:\work-project\ssi\odoo_demo\odoo\odoo\modules\loading.py", line 481, in load_modules
    processed_modules += load_marked_modules(env, graph,
                         ^^^^^^^^^^^^^^^^^^^^^^^^^^^^^^^
  File "D:\work-project\ssi\odoo_demo\odoo\odoo\modules\loading.py", line 366, in load_marked_modules
    loaded, processed = load_module_graph(
                        ^^^^^^^^^^^^^^^^^^
  File "D:\work-project\ssi\odoo_demo\odoo\odoo\modules\loading.py", line 229, in load_module_graph
    load_data(env, idref, mode, kind='data', package=package)
  File "D:\work-project\ssi\odoo_demo\odoo\odoo\modules\loading.py", line 73, in load_data
    tools.convert_file(env, package.name, filename, idref, mode, noupdate, kind)
  File "D:\work-project\ssi\odoo_demo\odoo\odoo\tools\convert.py", line 635, in convert_file
    convert_xml_import(env, module, fp, idref, mode, noupdate)
  File "D:\work-project\ssi\odoo_demo\odoo\odoo\tools\convert.py", line 701, in convert_xml_import
    obj.parse(doc.getroot())
  File "D:\work-project\ssi\odoo_demo\odoo\odoo\tools\convert.py", line 621, in parse
    self._tag_root(de)
  File "D:\work-project\ssi\odoo_demo\odoo\odoo\tools\convert.py", line 564, in _tag_root
    f(rec)
  File "D:\work-project\ssi\odoo_demo\odoo\odoo\tools\convert.py", line 577, in _tag_root
    raise ParseError('while parsing %s:%s, somewhere inside\n%s' % (
odoo.tools.convert.ParseError: while parsing file:/d:/work-project/ssi/odoo_demo/odoo/custom_addons/customer_map_tracking/views/customer_map_actions.xml:5, somewhere inside
<record id="action_customer_map_dashboard" model="ir.actions.act_window">
            <field name="name">Map Dashboard</field>
            <field name="res_model">customer.map</field>
            <field name="view_mode">geoengine,tree,form</field>
            <field name="view_id" ref="view_customer_map_geoengine_simple"/>
            <field name="domain">[('active', '=', True), ('shape', '!=', False)]</field>
            <field name="context">{
                'create': True,
                'edit': True,
                'delete': False
            }</field>
        </record>
2025-09-27 10:02:36,802 13768 ERROR ? odoo.http: Exception during request handling. 
Traceback (most recent call last):
  File "D:\work-project\ssi\odoo_demo\odoo\odoo\modules\registry.py", line 87, in __new__
    return cls.registries[db_name]
           ~~~~~~~~~~~~~~^^^^^^^^^
  File "D:\work-project\ssi\odoo_demo\odoo\venv\Lib\site-packages\decorator.py", line 232, in fun
    return caller(func, *(extras + args), **kw)
           ^^^^^^^^^^^^^^^^^^^^^^^^^^^^^^^^^^^^
  File "D:\work-project\ssi\odoo_demo\odoo\odoo\tools\func.py", line 87, in locked
    return func(inst, *args, **kwargs)
           ^^^^^^^^^^^^^^^^^^^^^^^^^^^
  File "D:\work-project\ssi\odoo_demo\odoo\odoo\tools\lru.py", line 34, in __getitem__
    a = self.d[obj]
        ~~~~~~^^^^^
KeyError: 'ssi_odoo_demo'

During handling of the above exception, another exception occurred:

Traceback (most recent call last):
  File "D:\work-project\ssi\odoo_demo\odoo\odoo\tools\cache.py", line 99, in lookup
    r = d[key]
        ~^^^^^
  File "D:\work-project\ssi\odoo_demo\odoo\venv\Lib\site-packages\decorator.py", line 232, in fun
    return caller(func, *(extras + args), **kw)
           ^^^^^^^^^^^^^^^^^^^^^^^^^^^^^^^^^^^^
  File "D:\work-project\ssi\odoo_demo\odoo\odoo\tools\func.py", line 87, in locked
    return func(inst, *args, **kwargs)
           ^^^^^^^^^^^^^^^^^^^^^^^^^^^
  File "D:\work-project\ssi\odoo_demo\odoo\odoo\tools\lru.py", line 34, in __getitem__
    a = self.d[obj]
        ~~~~~~^^^^^
KeyError: ('ir.model.data', <function IrModelData._xmlid_lookup at 0x00000151A4B33920>, 'customer_map_tracking.view_customer_map_geoengine_simple')

During handling of the above exception, another exception occurred:

Traceback (most recent call last):
  File "D:\work-project\ssi\odoo_demo\odoo\odoo\tools\convert.py", line 564, in _tag_root
    f(rec)
  File "D:\work-project\ssi\odoo_demo\odoo\odoo\tools\convert.py", line 429, in _tag_record
    f_val = self.id_get(f_ref, raise_if_not_found=nodeattr2bool(rec, 'forcecreate', True))
            ^^^^^^^^^^^^^^^^^^^^^^^^^^^^^^^^^^^^^^^^^^^^^^^^^^^^^^^^^^^^^^^^^^^^^^^^^^^^^^
  File "D:\work-project\ssi\odoo_demo\odoo\odoo\tools\convert.py", line 546, in id_get
    res = self.model_id_get(id_str, raise_if_not_found)
          ^^^^^^^^^^^^^^^^^^^^^^^^^^^^^^^^^^^^^^^^^^^^^
  File "D:\work-project\ssi\odoo_demo\odoo\odoo\tools\convert.py", line 552, in model_id_get
    return self.env['ir.model.data']._xmlid_to_res_model_res_id(id_str, raise_if_not_found=raise_if_not_found)
           ^^^^^^^^^^^^^^^^^^^^^^^^^^^^^^^^^^^^^^^^^^^^^^^^^^^^^^^^^^^^^^^^^^^^^^^^^^^^^^^^^^^^^^^^^^^^^^^^^^^
  File "D:\work-project\ssi\odoo_demo\odoo\odoo\addons\base\models\ir_model.py", line 2205, in _xmlid_to_res_model_res_id
    return self._xmlid_lookup(xmlid)
           ^^^^^^^^^^^^^^^^^^^^^^^^^
  File "D:\work-project\ssi\odoo_demo\odoo\venv\Lib\site-packages\decorator.py", line 232, in fun
    return caller(func, *(extras + args), **kw)
           ^^^^^^^^^^^^^^^^^^^^^^^^^^^^^^^^^^^^
  File "D:\work-project\ssi\odoo_demo\odoo\odoo\tools\cache.py", line 104, in lookup
    value = d[key] = self.method(*args, **kwargs)
                     ^^^^^^^^^^^^^^^^^^^^^^^^^^^^
  File "D:\work-project\ssi\odoo_demo\odoo\odoo\addons\base\models\ir_model.py", line 2198, in _xmlid_lookup
    raise ValueError('External ID not found in the system: %s' % xmlid)
ValueError: External ID not found in the system: customer_map_tracking.view_customer_map_geoengine_simple

The above exception was the direct cause of the following exception:

Traceback (most recent call last):
  File "D:\work-project\ssi\odoo_demo\odoo\odoo\http.py", line 2396, in __call__
    response = request._serve_db()
               ^^^^^^^^^^^^^^^^^^^
  File "D:\work-project\ssi\odoo_demo\odoo\odoo\http.py", line 1949, in _serve_db
    self.registry = Registry(self.db).check_signaling()
                    ^^^^^^^^^^^^^^^^^
  File "D:\work-project\ssi\odoo_demo\odoo\odoo\modules\registry.py", line 89, in __new__
    return cls.new(db_name)
           ^^^^^^^^^^^^^^^^
  File "D:\work-project\ssi\odoo_demo\odoo\venv\Lib\site-packages\decorator.py", line 232, in fun
    return caller(func, *(extras + args), **kw)
           ^^^^^^^^^^^^^^^^^^^^^^^^^^^^^^^^^^^^
  File "D:\work-project\ssi\odoo_demo\odoo\odoo\tools\func.py", line 87, in locked
    return func(inst, *args, **kwargs)
           ^^^^^^^^^^^^^^^^^^^^^^^^^^^
  File "D:\work-project\ssi\odoo_demo\odoo\odoo\modules\registry.py", line 110, in new
    odoo.modules.load_modules(registry, force_demo, status, update_module)
  File "D:\work-project\ssi\odoo_demo\odoo\odoo\modules\loading.py", line 481, in load_modules
    processed_modules += load_marked_modules(env, graph,
                         ^^^^^^^^^^^^^^^^^^^^^^^^^^^^^^^
  File "D:\work-project\ssi\odoo_demo\odoo\odoo\modules\loading.py", line 366, in load_marked_modules
    loaded, processed = load_module_graph(
                        ^^^^^^^^^^^^^^^^^^
  File "D:\work-project\ssi\odoo_demo\odoo\odoo\modules\loading.py", line 229, in load_module_graph
    load_data(env, idref, mode, kind='data', package=package)
  File "D:\work-project\ssi\odoo_demo\odoo\odoo\modules\loading.py", line 73, in load_data
    tools.convert_file(env, package.name, filename, idref, mode, noupdate, kind)
  File "D:\work-project\ssi\odoo_demo\odoo\odoo\tools\convert.py", line 635, in convert_file
    convert_xml_import(env, module, fp, idref, mode, noupdate)
  File "D:\work-project\ssi\odoo_demo\odoo\odoo\tools\convert.py", line 701, in convert_xml_import
    obj.parse(doc.getroot())
  File "D:\work-project\ssi\odoo_demo\odoo\odoo\tools\convert.py", line 621, in parse
    self._tag_root(de)
  File "D:\work-project\ssi\odoo_demo\odoo\odoo\tools\convert.py", line 564, in _tag_root
    f(rec)
  File "D:\work-project\ssi\odoo_demo\odoo\odoo\tools\convert.py", line 577, in _tag_root
    raise ParseError('while parsing %s:%s, somewhere inside\n%s' % (
odoo.tools.convert.ParseError: while parsing file:/d:/work-project/ssi/odoo_demo/odoo/custom_addons/customer_map_tracking/views/customer_map_actions.xml:5, somewhere inside
<record id="action_customer_map_dashboard" model="ir.actions.act_window">
            <field name="name">Map Dashboard</field>
            <field name="res_model">customer.map</field>
            <field name="view_mode">geoengine,tree,form</field>
            <field name="view_id" ref="view_customer_map_geoengine_simple"/>
            <field name="domain">[('active', '=', True), ('shape', '!=', False)]</field>
            <field name="context">{
                'create': True,
                'edit': True,
                'delete': False
            }</field>
        </record>
2025-09-27 10:02:36,805 13768 INFO ? werkzeug: 127.0.0.1 - - [27/Sep/2025 10:02:36] "GET /web/service-worker.js HTTP/1.1" 500 - 193 0.068 0.265
2025-09-27 10:02:45,051 13768 INFO ssi_odoo_demo odoo.service.server: Initiating shutdown 
2025-09-27 10:02:45,051 13768 INFO ssi_odoo_demo odoo.service.server: Hit CTRL-C again or send a second signal to force the shutdown. 
2025-09-27 10:02:46,116 13768 INFO ssi_odoo_demo odoo.sql_db: ConnectionPool(used=0/count=0/max=64): Closed 3 connections  
